Workbook

Sheet Stock y price
A1: PRODUCTO (A) | B1: PRECIO (B) | C1: (C) | D1: STOCK (D) | E1: (E) | F1: MARCA (F) | G1: CATEGORIA (G) | H1: COSTO | J1: COMISION | L1: Costo Aereo | M1: Aereo+costo | N1: Total costo | O1: PESO
A2: Peak Pro 3DXL - Onyx | B2: 380 | C2: C | D2: 0 | F2: PUFFCO | G2: VAPORIZADOR | H2: 317.43177 | I2: =(B2/H2)-1 -> 0.19710765 | J2: =(B2-H2)/2 -> 31.284115 | L2: =(O2*38) -> 30.058 | M2: =L2+268 -> 298.058 | N2: =M2*1.065 -> 317.43177 | O2: 0.791 | Q2: =H2*D2 -> 0
A3: Peak Pro 3DXL - Pearl | B3: 380 | C3: C | D3: 0 | F3: PUFFCO | G3: VAPORIZADOR | H3: 317.43177 | I3: =(B3/H3)-1 -> 0.19710765 | J3: =(B3-H3)/2 -> 31.284115 | L3: =(O3*38) -> 30.058 | M3: =L3+268 -> 298.058 | N3: =M3*1.065 -> 317.43177 | O3: 0.791 | Q3: =H3*D3 -> 0
A4: Peak Pro 3DXL - PLASMA | B4: 380 | C4: C | D4: 0 | F4: PUFFCO | G4: VAPORIZADOR | H4: 317.43177 | I4: =(B4/H4)-1 -> 0.19710765 | J4: =(B4-H4)/2 -> 31.284115 | L4: =(O4*38) -> 30.058 | M4: =L4+268 -> 298.058 | N4: =M4*1.065 -> 317.43177 | O4: 0.791 | Q4: =H4*D4 -> 0
A5: Proxy - Haze | B5: 230 | C5: C | D5: 9 | F5: PUFFCO | G5: VAPORIZADOR | H5: 190.11102 | I5: =(B5/H5)-1 -> 0.2098194 | J5: =(B5-H5)/2 -> 19.94449 | L5: =(O5*38) -> 21.508 | M5: =L5+157 -> 178.508 | N5: =M5*1.065 -> 190.11102 | O5: 0.566 | Q5: =H5*D5 -> 1710.9992
A6: Proxy - Onyx | B6: 230 | C6: C | D6: 0 | F6: PUFFCO | G6: VAPORIZADOR | H6: 190.11102 | I6: =(B6/H6)-1 -> 0.2098194 | J6: =(B6-H6)/2 -> 19.94449 | L6: =(O6*38) -> 21.508 | M6: =L6+157 -> 178.508 | N6: =M6*1.065 -> 190.11102 | O6: 0.566 | Q6: =H6*D6 -> 0
A7: Proxy Core PINE | B7: 210 | C7: C | D7: 2 | F7: PUFFCO | G7: VAPORIZADOR | H7: 173.78031 | I7: =(B7/H7)-1 -> 0.20842229 | J7: =(B7-H7)/2 -> 18.109845 | L7: =(O7*38) -> 14.174 | M7: =L7+149 -> 163.174 | N7: =M7*1.065 -> 173.78031 | O7: 0.373 | Q7: =H7*D7 -> 347.56062
A8: Proxy Core ONIX | B8: 210 | C8: C | D8: 0 | F8: PUFFCO | G8: VAPORIZADOR | H8: 173.78031 | I8: =(B8/H8)-1 -> 0.20842229 | J8: =(B8-H8)/2 -> 18.109845 | L8: =(O8*38) -> 14.174 | M8: =L8+149 -> 163.174 | N8: =M8*1.065 -> 173.78031 | O8: 0.373 | Q8: =H8*D8 -> 0
A9: Proxy Core silicona ONIX | B9: 50 | C9: C | D9: 3 | F9: PUFFCO | G9: ACCESORIO | H9: 32.802 | I9: =(B9/H9)-1 -> 0.5242973 | J9: =(B9-H9)/2 -> 8.599 | L9: =(O9*38) -> 3.8 | M9: =L9+27 -> 30.8 | N9: =M9*1.065 -> 32.802 | O9: 0.1 | Q9: =H9*D9 -> 98.406
A10: Proxy Core silicona HAZE | B10: 50 | C10: C | D10: 6 | F10: PUFFCO | G10: ACCESORIO | H10: 32.802 | I10: =(B10/H10)-1 -> 0.5242973 | J10: =(B10-H10)/2 -> 8.599 | L10: =(O10*38) -> 3.8 | M10: =L10+27 -> 30.8 | N10: =M10*1.065 -> 32.802 | O10: 0.1 | Q10: =H10*D10 -> 196.812
A11: Pivot - Storm | B11: 120 | C11: C | D11: 1 | F11: PUFFCO | G11: VAPORIZADOR | H11: 98.7681 | I11: =(B11/H11)-1 -> 0.21496718 | J11: =(B11-H11)/2 -> 10.61595 | L11: =(O11*38) -> 8.74 | M11: =L11+84 -> 92.74 | N11: =M11*1.065 -> 98.7681 | O11: 0.23 | Q11: =H11*D11 -> 98.7681
A12: Pivot - Onyx | B12: 120 | C12: C | D12: 3 | F12: PUFFCO | G12: VAPORIZADOR | H12: 98.7681 | I12: =(B12/H12)-1 -> 0.21496718 | J12: =(B12-H12)/2 -> 10.61595 | L12: =(O12*38) -> 8.74 | M12: =L12+84 -> 92.74 | N12: =M12*1.065 -> 98.7681 | O12: 0.23 | Q12: =H12*D12 -> 296.3043
A13: Peak - Amarillo | B13: 215 | C13: C | D13: 3 | F13: PUFFCO | G13: VAPORIZADOR | H13: 185.1396 | I13: =(B13/H13)-1 -> 0.16128586 | J13: =(B13-H13)/2 -> 14.9302 | L13: =(O13*38) -> 25.84 | M13: =L13+148 -> 173.84 | N13: =M13*1.065 -> 185.1396 | O13: 0.68 | Q13: =H13*D13 -> 555.4188
A14: Peak - Storm | B14: 215 | C14: C | D14: 0 | F14: PUFFCO | G14: VAPORIZADOR | H14: 185.1396 | I14: =(B14/H14)-1 -> 0.16128586 | J14: =(B14-H14)/2 -> 14.9302 | L14: =(O14*38) -> 25.84 | M14: =L14+148 -> 173.84 | N14: =M14*1.065 -> 185.1396 | O14: 0.68 | Q14: =H14*D14 -> 0
A15: Peak - Onyx | B15: 215 | C15: C | D15: 0 | F15: PUFFCO | G15: VAPORIZADOR | H15: 185.1396 | I15: =(B15/H15)-1 -> 0.16128586 | J15: =(B15-H15)/2 -> 14.9302 | L15: =(O15*38) -> 25.688 | M15: =L15+148 -> 173.688 | N15: =M15*1.065 -> 184.97772 | O15: 0.676 | Q15: =H15*D15 -> 0
A16: Proxy Bub - Haze | B16: 90 | C16: C | D16: 4 | F16: PUFFCO | G16: ACCESORIO | H16: 70.65636 | I16: =(B16/H16)-1 -> 0.27377068 | J16: =(B16-H16)/2 -> 9.67182 | L16: =(O16*38) -> 12.844 | M16: =L16+53.5 -> 66.344 | N16: =M16*1.065 -> 70.65636 | O16: 0.338 | Q16: =H16*D16 -> 282.62544
A17: Proxy Bub - Onyx | B17: 90 | C17: C | D17: 0 | F17: PUFFCO | G17: ACCESORIO | H17: 70.65636 | I17: =(B17/H17)-1 -> 0.27377068 | J17: =(B17-H17)/2 -> 9.67182 | L17: =(O17*38) -> 12.844 | M17: =L17+53.5 -> 66.344 | N17: =M17*1.065 -> 70.65636 | O17: 0.338 | Q17: =H17*D17 -> 0
A18: Proxy Bub Wizard - Haze | B18: 90 | C18: C | D18: 0 | F18: PUFFCO | G18: ACCESORIO | H18: 71.02059 | I18: =(B18/H18)-1 -> 0.26723813 | J18: =(B18-H18)/2 -> 9.489705 | L18: =(O18*38) -> 13.186 | M18: =L18+53.5 -> 66.686 | N18: =M18*1.065 -> 71.02059 | O18: 0.347 | Q18: =H18*D18 -> 0
A19: Proxy Bub Wizard - Onyx | B19: 90 | C19: C | D19: 2 | F19: PUFFCO | G19: ACCESORIO | H19: 71.02059 | I19: =(B19/H19)-1 -> 0.26723813 | J19: =(B19-H19)/2 -> 9.489705 | L19: =(O19*38) -> 13.186 | M19: =L19+53.5 -> 66.686 | N19: =M19*1.065 -> 71.02059 | O19: 0.347 | Q19: =H19*D19 -> 142.04118
A20: Proxy Bub viejo - Onyx | B20: 90 | C20: C | D20: 0 | F20: PUFFCO | G20: ACCESORIO | H20: 71.142 | I20: =(B20/H20)-1 -> 0.26507548 | J20: =(B20-H20)/2 -> 9.429 | L20: =(O20*38) -> 13.3 | M20: =L20+53.5 -> 66.8 | N20: =M20*1.065 -> 71.142 | O20: 0.35 | Q20: =H20*D20 -> 0
A21: Proxy wizard - marron | B21: 100 | C21: C | D21: 0 | F21: PUFFCO | G21: ACCESORIO | H21: 73 | I21: =(B21/H21)-1 -> 0.36986301 | J21: =(B21-H21)/2 -> 13.5 | L21: =(O21*38) -> 13.3 | M21: =L21+55 -> 68.3 | N21: =M21*1.065 -> 72.7395 | O21: 0.35 | Q21: =H21*D21 -> 0
A22: Peak Pro 3DXL Chamber clasico | B22: 80 | C22: C | D22: 0 | F22: PUFFCO | G22: REPUESTO | H22: 57.297 | I22: =(B22/H22)-1 -> 0.39623366 | J22: =(B22-H22)/2 -> 11.3515 | L22: =(O22*38) -> 3.8 | M22: =L22+50 -> 53.8 | N22: =M22*1.065 -> 57.297 | O22: 0.1 | Q22: =H22*D22 -> 0
A23: Peak Pro 3DXL Chamber - PLASMA | B23: 80 | C23: C | D23: 17 | F23: PUFFCO | G23: REPUESTO | H23: 57.297 | I23: =(B23/H23)-1 -> 0.39623366 | J23: =(B23-H23)/2 -> 11.3515 | L23: =(O23*38) -> 3.8 | M23: =L23+50 -> 53.8 | N23: =M23*1.065 -> 57.297 | O23: 0.1 | Q23: =H23*D23 -> 974.049
A24: Hot knife NEW NEGRO | B24: 60 | C24: C | D24: 3 | F24: PUFFCO | G24: ACCESORIO | H24: 46.647 | I24: =(B24/H24)-1 -> 0.28625635 | J24: =(B24-H24)/2 -> 6.6765 | L24: =(O24*38) -> 3.8 | M24: =L24+40 -> 43.8 | N24: =M24*1.065 -> 46.647 | O24: 0.1 | Q24: =H24*D24 -> 139.941
A25: Hot knife NEW PEARL | B25: 60 | C25: C | D25: 2 | F25: PUFFCO | G25: ACCESORIO | H25: 46.647 | I25: =(B25/H25)-1 -> 0.28625635 | J25: =(B25-H25)/2 -> 6.6765 | L25: =(O25*38) -> 3.8 | M25: =L25+40 -> 43.8 | N25: =M25*1.065 -> 46.647 | O25: 0.1 | Q25: =H25*D25 -> 93.294
A26: Hot Knife NEW PINE | B26: 60 | C26: C | D26: 3 | F26: PUFFCO | G26: ACCESORIO | H26: 46.647 | I26: =(B26/H26)-1 -> 0.28625635 | J26: =(B26-H26)/2 -> 6.6765 | L26: =(O26*38) -> 3.8 | M26: =L26+40 -> 43.8 | N26: =M26*1.065 -> 46.647 | O26: 0.1 | Q26: =H26*D26 -> 139.941
A27: Hot Knife NEW PLASMA | B27: 60 | C27: C | D27: 0 | F27: PUFFCO | G27: ACCESORIO | H27: 46.647 | I27: =(B27/H27)-1 -> 0.28625635 | J27: =(B27-H27)/2 -> 6.6765 | L27: =(O27*38) -> 3.8 | M27: =L27+40 -> 43.8 | N27: =M27*1.065 -> 46.647 | O27: 0.1 | Q27: =H27*D27 -> 0
A28: BAG PEAK PRO | B28: 50 | C28: C | D28: 0 | F28: PUFFCO | G28: ACCESORIO | H28: 39.34 | I28: =(B28/H28)-1 -> 0.27097102 | J28: =(B28-H28)/2 -> 5.33 | L28: =(O28*38) -> #N/A | M28: =L28+250 -> #N/A | N28: =M28*1.065 -> #N/A | O28: #N/A | Q28: =H28*D28 -> 0
A29: Peak Pro 3D Chamber | B29: 70 | C29: C | D29: 0 | F29: PUFFCO | G29: REPUESTO | H29: 52.3767 | I29: =(B29/H29)-1 -> 0.33647213 | J29: =(B29-H29)/2 -> 8.81165 | L29: =(O29*38) -> 4.18 | M29: =L29+45 -> 49.18 | N29: =M29*1.065 -> 52.3767 | O29: 0.11 | Q29: =H29*D29 -> 0
A30: Peak Pro TRAVEL GLASS SHADOW | B30: 85 | C30: C | D30: 0 | F30: PUFFCO | G30: ACCESORIO | H30: 57.946 | I30: =(B30/H30)-1 -> 0.46688296 | J30: =(B30-H30)/2 -> 13.527 | L30: =(O30*38) -> #N/A | M30: =L30+61 -> #N/A | N30: =M30*1.065 -> #N/A | O30: #N/A | Q30: =H30*D30 -> 0
A31: Peak Pro TRAVEL GLASS | B31: 85 | C31: C | D31: 0 | F31: PUFFCO | G31: ACCESORIO | H31: 57.946 | I31: =(B31/H31)-1 -> 0.46688296 | J31: =(B31-H31)/2 -> 13.527 | L31: =(O31*38) -> #N/A | M31: =L31+61 -> #N/A | N31: =M31*1.065 -> #N/A | O31: #N/A | Q31: =H31*D31 -> 0
A32: Peak Pro Glass 2.0 | B32: 75 | C32: C | D32: 5 | F32: PUFFCO | G32: ACCESORIO | H32: 57.946 | I32: =(B32/H32)-1 -> 0.29430849 | J32: =(B32-H32)/2 -> 8.527 | L32: =(O32*38) -> #N/A | M32: =L32+53.5 -> #N/A | N32: =M32*1.065 -> #N/A | O32: #N/A | Q32: =H32*D32 -> 289.73
A33: Proxy 3D Chamber - Onyx | B33: 37 | C33: C | D33: 14 | F33: PUFFCO | G33: REPUESTO | H33: 29.80722 | I33: =(B33/H33)-1 -> 0.24130999 | J33: =(B33-H33)/2 -> 3.59639 | L33: =(O33*38) -> 0.988 | M33: =L33+27 -> 27.988 | N33: =M33*1.065 -> 29.80722 | O33: 0.026 | Q33: =H33*D33 -> 417.30108
A34: Peak 3D Chamber - Onyx | B34: 45 | C34: C | D34: 49 | F34: PUFFCO | G34: REPUESTO | H34: 36.97893 | I34: =(B34/H34)-1 -> 0.2169092 | J34: =(B34-H34)/2 -> 4.010535 | L34: =(O34*38) -> 0.722 | M34: =L34+34 -> 34.722 | N34: =M34*1.065 -> 36.97893 | O34: 0.019 | Q34: =H34*D34 -> 1811.9676
A35: Pivot 3D Chamber 2-Pack - Onyx | B35: 55 | C35: C | D35: 24 | F35: PUFFCO | G35: REPUESTO | H35: 37.45179 | I35: =(B35/H35)-1 -> 0.46855464 | J35: =(B35-H35)/2 -> 8.774105 | L35: =(O35*38) -> 2.166 | M35: =L35+33 -> 35.166 | N35: =M35*1.065 -> 37.45179 | O35: 0.057 | Q35: =H35*D35 -> 898.84296
A36: Pivot Glass Adapter with 3D Chamber - Onyx | B36: 60 | C36: C | D36: 6 | F36: PUFFCO | G36: ACCESORIO | H36: 43.15593 | I36: =(B36/H36)-1 -> 0.3903072 | J36: =(B36-H36)/2 -> 8.422035 | L36: =(O36*38) -> 4.522 | M36: =L36+36 -> 40.522 | N36: =M36*1.065 -> 43.15593 | O36: 0.119 | Q36: =H36*D36 -> 258.93558
A37: Plus Dark Pack | B37: 10 | C37: C | D37: 0 | F37: PUFFCO | G37: ACCESORIO | H37: 5.06 | I37: =(B37/H37)-1 -> 0.97628459 | J37: =(B37-H37)/2 -> 2.47 | L37: =(O37*38) -> #N/A | M37: =L37+250 -> #N/A | N37: =M37*1.065 -> #N/A | O37: #N/A | Q37: =H37*D37 -> 0
A38: Plus Supercharger | B38: 4 | C38: C | D38: 0 | F38: PUFFCO | G38: ACCESORIO | H38: 5.06 | I38: =(B38/H38)-1 -> -0.20948617 | J38: =(B38-H38)/2 -> -0.53 | L38: =(O38*38) -> #N/A | M38: =L38+250 -> #N/A | N38: =M38*1.065 -> #N/A | O38: #N/A | Q38: =H38*D38 -> 0
A39: Plus Battery - Pearl | B39: 25 | C39: C | D39: 0 | F39: PUFFCO | G39: REPUESTO | H39: 32.492 | I39: =(B39/H39)-1 -> -0.23057984 | J39: =(B39-H39)/2 -> -3.746 | L39: =(O39*38) -> 6.992 | M39: =L39+250 -> 256.992 | N39: =M39*1.065 -> 273.69648 | O39: 0.184 | Q39: =H39*D39 -> 0
A40: Chamber Plus - Pearl | B40: 15 | C40: C | D40: 0 | F40: PUFFCO | G40: REPUESTO | H40: 11 | I40: =(B40/H40)-1 -> 0.36363636 | J40: =(B40-H40)/2 -> 2 | L40: =(O40*38) -> #N/A | M40: =L40+250 -> #N/A | N40: =M40*1.065 -> #N/A | O40: #N/A | Q40: =H40*D40 -> 0
...

Sheet Resumen
A1: Cliente | B1: Saldo | E1: TOTAL DEUDA | F1: =SUM(B2:B982) -> 49255.195
A2: TIN UY | B2: =INDIRECT("'" & A2 & "'!I1") -> 10639.221 | J2: H1 | K2: 16999
A3: Facu Pisando | B3: =INDIRECT("'" & A3 & "'!I1") -> 7052.3677 | J3: H7 | K3: 16999
A4: Guille naesa | B4: =INDIRECT("'" & A4 & "'!I1") -> 2912.7268 | J4: H4 | K4: 22999
A5: FACU LP | B5: =INDIRECT("'" & A5 & "'!I1") -> 3477 | J5: A232-7A | K5: 169999
A6: Kanario | B6: =INDIRECT("'" & A6 & "'!I1") -> 2909.6785 | J6: RF-5020 | K6: 24999
A7: LT Grow | B7: =INDIRECT("'" & A7 & "'!I1") -> 1426.8722 | J7: ST-KIT08 | K7: 22999
A8: MARSHAL LEAN | B8: =INDIRECT("'" & A8 & "'!I1") -> 2551.5 | J8: ST-KIT04 | K8: 33999
A9: Alfredo Indajaus | B9: =INDIRECT("'" & A9 & "'!I1") -> 2480 | J9: ST-03 | K9: 6999
A10: vaporever | B10: =INDIRECT("'" & A10 & "'!I1") -> 2952.3634 | J10: ST-ISO45080 | K10: 6499
A11: The pot club | B11: =INDIRECT("'" & A11 & "'!I1") -> 1985 | J11: ST-CABPRO2V | K11: 36999
A12: Alto Vuelo | B12: =INDIRECT("'" & A12 & "'!I1") -> 1501
A13: Pedro | B13: =INDIRECT("'" & A13 & "'!I1") -> 1467.7487
A14: Leloir ONG | B14: =INDIRECT("'" & A14 & "'!I1") -> 1315
A15: Alan | B15: =INDIRECT("'" & A15 & "'!I1") -> 950.23259
A16: Nahu La comarca | B16: =INDIRECT("'" & A16 & "'!I1") -> 733
A17: Lean TEGRIDAD | B17: =INDIRECT("'" & A17 & "'!I1") -> 309.76288
A18: Ale Ong Cordoba | B18: =INDIRECT("'" & A18 & "'!I1") -> 482
A19: Tuki Grow | B19: =INDIRECT("'" & A19 & "'!I1") -> 430
A20: Coco Salta | B20: =INDIRECT("'" & A20 & "'!I1") -> 2083.0266
A21: Agus Honney | B21: =INDIRECT("'" & A21 & "'!I1") -> 68.659953
A22: High up OMG | B22: =INDIRECT("'" & A22 & "'!I1") -> 0
A23: OLD FARMERS | B23: =INDIRECT("'" & A23 & "'!I1") -> 1528.0369
A24: Charly Distri | B24: =INDIRECT("'" & A24 & "'!I1") -> -0.002455

Sheet LISTA Special distro
A1: PRODUCTO | B1: VENTA | C1: DISTRI
A2: {=IF('Stock y price'!A2:A1643="", "", 'Stock y price'!A2:A1643)} -> Peak Pro 3DXL - Onyx | B2: {=IF('Stock y price'!A2:A1643="", "", 'Stock y price'!B2:B1643)} -> 380 | C2: {=IF('Stock y price'!A2:A1643="", "", 'Stock y price'!H2:H1643 + ('Stock y price'!B2:B1643 - 'Stock y price'!H2:H1643) / 2)} -> 348.71589 | D2: =(B2/C2)-1 -> 0.089712331
A3: Peak Pro 3DXL - Pearl | B3: 380 | C3: 348.71588 | D3: =(B3/C3)-1 -> 0.089712331
A4: Peak Pro 3DXL - PLASMA | B4: 380 | C4: 348.71588 | D4: =(B4/C4)-1 -> 0.089712331
A5: Proxy - Haze | B5: 230 | C5: 210.05551 | D5: =(B5/C5)-1 -> 0.094948664
A6: Proxy - Onyx | B6: 230 | C6: 210.05551 | D6: =(B6/C6)-1 -> 0.094948664
A7: Proxy Core PINE | B7: 210 | C7: 191.89015 | D7: =(B7/C7)-1 -> 0.094376103
A8: Proxy Core ONIX | B8: 210 | C8: 191.89015 | D8: =(B8/C8)-1 -> 0.094376103
A9: Proxy Core silicona ONIX | B9: 50 | C9: 41.401 | D9: =(B9/C9)-1 -> 0.2077003
A10: Proxy Core silicona HAZE | B10: 50 | C10: 41.401 | D10: =(B10/C10)-1 -> 0.2077003
A11: Pivot - Storm | B11: 120 | C11: 109.38405 | D11: =(B11/C11)-1 -> 0.097052084
A12: Pivot - Onyx | B12: 120 | C12: 109.38405 | D12: =(B12/C12)-1 -> 0.097052084
A13: Peak - Amarillo | B13: 215 | C13: 200.0698 | D13: =(B13/C13)-1 -> 0.074624956
A14: Peak - Storm | B14: 215 | C14: 200.0698 | D14: =(B14/C14)-1 -> 0.074624956
... A298: MJ Arsenal Proxy Attachments - 14mm 45deg | B298: 20 | C298: 15.00337 | D298: =(B298/C298)-1 -> 0.33303385
A300: FORMULA 420 PYREX-GLASS-METAL-CERAMIC Al 12oz 24ct | B300: 9 | C300: 7.545
A301: Formula 710 Advanced Cleaner C 1_16oz_20ct | B301: 12 | C301: 9.945
A302: Formula 710 Instant Cleaner C2_12oz_24ct | B302: 9 | C302: 7.545
A303: Dab Rite GO | B303: 299 | C303: 267.502
A309: SLURPER MOPS (LIMPIEZA DE BONGS) | B309: 15 | C309: 7.5
A310: GLOB MOPS CLASICO | B310: 12 | C310: 6
A311: GLOB MOPS BENDABLE (SE DOBLA EL CABO DEL MOPS) | B311: 12 | C311: 6
A312: KIT HIBRIDO (incluye pad antideslizante, cap/dabber, controlador, resistencia, cazuela) | B312: 330 | C312: 165
A313: KIT CUARZO (incluye pad antideslizante, cap/dabber, controlador, resistencia, cazuela) | B313: 310 | C313: 155
A314: Deep Dish Quartz Hybrid Nail (cazuela hibrida para 14-18 mm) | B314: 110 | C314: 55
A315: Quartz deep dish (REPUESTO cazuela de cuarzo para banger híbrido x 2 u) | B315: 25 | C315: 12.5
A316: Quartz Ebanger 14 mm Macho | B316: 30 | C316: 23.675
... A363: TERP BALL 3mm x 3 unidades | B363: 10 | C363: 7.5

Sheet Pedidos
A1: fecha | B1: Clientes | C1: Inversion inicial | D1: PEDIDO | E1: GANANCIA | F1: Ganancia real | I1: PAGO | J1: DEBE | K1: OBSERVACIONES
A2: 46065.556 | B2: Alfredo Indajaus | C2: 1 x Peak - Canyon, 1 x Hot knife Negro | D2: 240 | E2: 55.972 | F2: =IFERROR(__xludf.DUMMYFUNCTION("ARRAYFORMULA(IF(B2:B292="""", """",IF(REGEXMATCH(LOWER(B2:B292),""tin uy|charly distri|agus honney""),E2:E292/2, E2:E292)))"),55.97200000000001) -> 55.972 | I2: 240
A3: 46065.559 | B3: Leloir ong | C3: 2 x Pivot - Onyx, 2 x Pivot Pine, 1 x Proxy - Haze, 1 x Peak - Canyon, 1 x Peak Pro 3DXL - Pearl, 1 x Peak Pro 3DXL Chamber - Black, 1 x Pivot 3D Chamber 2-Pack - Onyx | D3: 1315 | E3: 326.428 | F3: =IFERROR(__xludf.DUMMYFUNCTION("""COMPUTED_VALUE"""),326.42800000000005) -> 326.428 | I3: 1315
A4: 46065.566 | B4: tin uy | C4: 5 x Pivot Pine, 6 x Pivot - Onyx, 2 x Peak - Pine, 1 x Peak - Canyon, 1 x Peak - Onyx, 2 x Peak Pro 3DXL - Onyx, 1 x Peak Pro 3DXL - Pearl, 2 x Proxy - Onyx, 2 x Proxy - Haze, 3 x Peak Pro 3DXL Chamber - Black, 3 x Peak 3D Chamber - Onyx, 7 x Adaptador Peak Pro Link, 2 x Hot knife Pearl, 1 x Hot knife Negro | D4: 5185 | E4: 1260.006 | F4: =IFERROR(__xludf.DUMMYFUNCTION("""COMPUTED_VALUE"""),630.0029999999999) -> 630.003
A5: 46065.572 | B5: flavio VIERCOLES | C5: 1 x Peak Pro 3DXL - Pearl, 1 x Hot knife Pearl | D5: 400 | E5: 80.602 | F5: =IFERROR(__xludf.DUMMYFUNCTION("""COMPUTED_VALUE"""),80.602) -> 80.602 | I5: 100 | J5: 300 dls
A6: 46065.573 | B6: COCO Salta 420 | C6: 2 x Adaptador Peak Pro Link, 1 x Proxy - Haze | D6: 440 | E6: 105.168 | F6: =IFERROR(__xludf.DUMMYFUNCTION("""COMPUTED_VALUE"""),105.16799999999998) -> 105.168 | J6: 440 dls
A7: 46065.576 | B7: Dealer del OESTE NQN Franco | C7: 1 x Peak Pro 3DXL - Onyx, 1 x Peak - Canyon, 1 x Proxy - Haze, 1 x Proxy - Onyx, 2 x Peak Pro 3DXL Chamber - Black, 2 x Adaptador Peak Pro Link, 1 x Peak Pro 3DXL - Pearl | D7: 1690 | E7: 387.472 | F7: =IFERROR(__xludf.DUMMYFUNCTION("""COMPUTED_VALUE"""),387.472) -> 387.472 | I7: 350
A8: 46065.586 | B8: CHARLY DISTRI | C8: 5 x Pivot Pine, 5 x Pivot - Onyx, 4 x Pivot Glass Adapter with 3D Chamber - Onyx, 5 x Hot knife Pearl, 5 x Hot knife Negro, 3 x Peak - Pine, 2 x Peak - Canyon, 2 x Peak - Onyx, 4 x Peak 3D Chamber - Onyx, 2 x Proxy - Onyx, 2 x Proxy - Haze, 2 x Proxy 3D Chamber - Onyx, 2 x Peak Pro 3DXL - Onyx, 2 x Peak Pro 3DXL - Pearl, 4 x Peak Pro 3DXL Chamber clasico, 4 x Peak Pro 3DXL Chamber - Black, 2 x Peak Pro Glass 2.0, 1 x Adaptador Peak Pro Link | D8: 6534 | E8: 1600.578 | F8: =IFERROR(__xludf.DUMMYFUNCTION("""COMPUTED_VALUE"""),800.289) -> 800.289 | J8: 6534 | K8: es mas por cosas que tenia yo | L8: 7400 aprox
A9: 46065.589 | B9: BIG FACU COSTA ATLANTICA | C9: 1 x Pivot Pine, 1 x Pivot - Onyx, 1 x Pivot 3D Chamber 2-Pack - Onyx, 1 x Pivot Glass Adapter with 3D Chamber - Onyx, 1 x Hot knife Negro, 1 x Hot knife Pearl, 1 x Peak - Canyon, 1 x Peak - Pine, 1 x Proxy - Haze, 2 x Proxy - Onyx, 1 x Peak Pro 3DXL - Pearl, 1 x Peak Pro 3DXL Chamber - Black, 2 x Adaptador Peak Pro Link | D9: 2085 | E9: 500.678 | F9: =IFERROR(__xludf.DUMMYFUNCTION("""COMPUTED_VALUE"""),500.678) -> 500.678 | I9: 800 | J9: 2231 dls
A10: 46065.598 | B10: Planto Luego existo | C10: 2 x Pivot Pine, 2 x Pivot - Onyx, 2 x Pivot 3D Chamber 2-Pack - Onyx, 1 x Hot knife Negro, 1 x Hot knife Pearl, 2 x Peak - Pine, 1 x Peak - Onyx, 1 x Peak - Canyon, 1 x Peak Pro 3DXL - Onyx, 1 x Peak Pro 3DXL - Pearl, 1 x Proxy - Haze, 2 x Proxy - Onyx, 4 x Proxy 3D Chamber - Onyx, 2 x Adaptador Peak Pro Link, 2 x Peak Pro 3DXL Chamber - Black | D10: 3258 | E10: 784.976 | F10: =IFERROR(__xludf.DUMMYFUNCTION("""COMPUTED_VALUE"""),784.9759999999999) -> 784.976 | I10: 3258 | K10: 46094
A11: 46065.605 | B11: High up OMG | C11: 30 x Plus Battery - Pearl, 2 x Proxy - Onyx, 4 x Proxy 3D Chamber - Onyx, 2 x Peak Pro 3DXL - Pearl, 1 x Proxy - Haze, 2 x Pivot Pine, 2 x Hot knife Negro, 2 x Hot knife Pearl, 3 x Peak - Onyx, 1 x Peak - Canyon, 1 x Peak - Pine | D11: 3868 | E11: 711.368 | F11: =IFERROR(__xludf.DUMMYFUNCTION("""COMPUTED_VALUE"""),711.368) -> 711.368 | I11: 4384 | K11: cobrado 26/2/2026 x luke entrego al colo 2-3-26
A12: 46065.606 | B12: High up OMG | C12: 2 x Peak Pro 3DXL Chamber clasico | D12: 160 | E12: 53.616 | F12: =IFERROR(__xludf.DUMMYFUNCTION("""COMPUTED_VALUE"""),53.616) -> 53.616 | J12: -
A13: 46065.612 | B13: High up OMG | C13: 1 x Peak - Canyon | D13: 190 | E13: 45.312 | F13: =IFERROR(__xludf.DUMMYFUNCTION("""COMPUTED_VALUE"""),45.31200000000001) -> 45.312 | J13: -
A14: 46066.452 | B14: Facu LP | C14: 1 x Peak Pro 3DXL - Onyx, 1 x Peak Pro 3DXL - Pearl | D14: 700 | E14: 139.884 | F14: =IFERROR(__xludf.DUMMYFUNCTION("""COMPUTED_VALUE"""),139.88400000000001) -> 139.884 | J14: 700 dls
A15: 46066.475 | B15: Astro GRow LA PLATA | C15: 2 x Pivot - Onyx, 1 x Pivot Pine, 1 x Peak - Onyx, 3 x Peak Atomizer, 1 x Proxy - Onyx, 1 x Proxy - Haze, 1 x Peak Pro 3DXL Chamber - Black | D15: 1084 | E15: 268.388 | F15: =IFERROR(__xludf.DUMMYFUNCTION("""COMPUTED_VALUE"""),268.38800000000003) -> 268.388 | I15: 1084
A16: 46066.487 | B16: Facu LP | C16: 1 x Peak Pro 3D Chamber | D16: 70 | E16: 20.82 | F16: =IFERROR(__xludf.DUMMYFUNCTION("""COMPUTED_VALUE"""),20.82) -> 20.82 | I16: 70
A17: 46066.488 | B17: tin uy | C17: 2 x Pivot Pine, 1 x Pivot - Onyx, 1 x Hot knife Negro | D17: 380 | E17: 101.44 | F17: =IFERROR(__xludf.DUMMYFUNCTION("""COMPUTED_VALUE"""),50.720000000000006) -> 50.72
A18: 46066.489 | B18: tin uy | C18: 2 x Peak Pro 3D Chamber | D18: 140 | E18: 41.64 | F18: =IFERROR(__xludf.DUMMYFUNCTION("""COMPUTED_VALUE"""),20.82) -> 20.82
A19: 46066.691 | B19: MARSHAL LEAN | C19: 1 x Peak Pro 3DXL - Pearl, 1 x Pivot Pine, 1 x Pivot - Onyx, 2 x Proxy - Onyx, 2 x Proxy - Haze, 1 x Peak 3D Chamber - Onyx, 2 x Peak Pro Glass 2.0, 3 x Peak Pro 3DXL Chamber - Black, 1 x Hot knife Negro | D19: 1855 | E19: 440.9 | F19: =IFERROR(__xludf.DUMMYFUNCTION("""COMPUTED_VALUE"""),440.9) -> 440.9 | J19: 1855
A20: 46066.856 | B20: Jamrock | C20: 1 x Pivot Pine, 1 x Peak - Pine, 1 x Peak Pro Glass 2.0 | D20: 375 | E20: 92.626 | F20: =IFERROR(__xludf.DUMMYFUNCTION("""COMPUTED_VALUE"""),92.62600000000002) -> 92.626 | I20: 375
A21: 46066.875 | B21: El club de la alegría | C21: 1 x Pivot - Onyx | D21: 110 | E21: 30.26 | F21: =IFERROR(__xludf.DUMMYFUNCTION("""COMPUTED_VALUE"""),30.260000000000005) -> 30.26 | I21: 110
A22: 46071.321 | B22: tin uy | C22: 3 x Proxy - Onyx, 2 x Pivot 3D Chamber 2-Pack - Onyx | D22: 710 | E22: 170.144 | F22: =IFERROR(__xludf.DUMMYFUNCTION("""COMPUTED_VALUE"""),85.07199999999999) -> 85.072
A23: 46071.328 | B23: tin uy | C23: 1 x Pivot Pine | D23: 110 | E23: 30.26 | F23: =IFERROR(__xludf.DUMMYFUNCTION("""COMPUTED_VALUE"""),15.130000000000003) -> 15.13
A24: 46071.362 | B24: tin uy | C24: 1 x Pivot - Onyx | D24: 110 | E24: 30.26 | F24: =IFERROR(__xludf.DUMMYFUNCTION("""COMPUTED_VALUE"""),15.130000000000003) -> 15.13
A25: 46072.992 | B25: tin uy | C25: 1 x Peak Pro Glass 2.0 | D25: 75 | E25: 17.054 | F25: =IFERROR(__xludf.DUMMYFUNCTION("""COMPUTED_VALUE"""),8.527000000000001) -> 8.527
A26: 46073.357 | B26: Agus HONNEY | C26: 1 x Peak - Pine, 2 x GLOB MOPS CLASICO | D26: 214 | E26: 69.312 | F26: =IFERROR(__xludf.DUMMYFUNCTION("""COMPUTED_VALUE"""),34.656000000000006) -> 34.656 | I26: 214
A27: 46073 | B27: tin uy | C27: DEUDA ANTERIOR | D27: 154 | F27: =IFERROR(__xludf.DUMMYFUNCTION("""COMPUTED_VALUE"""),0.0) -> 0
A28: 46073.563 | B28: Facu LP | C28: 1 x Pivot Pine, 1 x Pivot 3D Chamber 2-Pack - Onyx, 1 x Peak Pro 3DXL Chamber clasico, 1 x Hot knife Pearl | D28: 295 | E28: 87.562 | F28: =IFERROR(__xludf.DUMMYFUNCTION("""COMPUTED_VALUE"""),87.56200000000001) -> 87.562 | J28: 295
A29: 46076.37 | B29: Tin UY | C29: 2 x PAPEL REYNOLS, 5 x GLOB MOPS CLASICO, 1 x Peak - Pine, 1 x Proxy - Haze, 1 x PUFFCO TRAVEL CASE ROJO, 1 x Joystick cap Peak New, 1 x Hot knife Negro, 1 x Hot knife Pearl | D29: 680 | E29: 257.604 | F29: =IFERROR(__xludf.DUMMYFUNCTION("""COMPUTED_VALUE"""),128.802) -> 128.802
A30: 46077.388 | B30: Jamrock | C30: 1 x Adaptador Peak Pro Link | D30: 120 | E30: 30.838 | F30: =IFERROR(__xludf.DUMMYFUNCTION("""COMPUTED_VALUE"""),30.837999999999994) -> 30.838 | I30: 120
A31: 46077.41 | B31: Tin UY | C31: 6 x Adaptador Peak Pro Link | D31: 720 | E31: 185.028 | F31: =IFERROR(__xludf.DUMMYFUNCTION("""COMPUTED_VALUE"""),92.51399999999998) -> 92.514
A32: 46077.424 | B32: FACU LP | C32: 1 x Proxy - Haze, 1 x Proxy - Onyx, 1 x Pivot - Onyx, 3 x Peak - Onyx, 1 x Peak - Canyon, 6 x Peak Pro 3DXL Chamber - Black | D32: 1750 | E32: 459.34 | F32: =IFERROR(__xludf.DUMMYFUNCTION("""COMPUTED_VALUE"""),459.34000000000003) -> 459.34 | J32: 1750
B33: FACU LP | C33: Deuda ANTERIOR | D33: 725
A34: 46077.647 | B34: MARSHAL LEAN | C34: 5 x Adaptador Peak Pro Link, 3 x MALLAS PARA BUBBLE HASH 20 LITROS PACK x 8 unidades | D34: 1410 | E34: 291.35 | F34: =IFERROR(__xludf.DUMMYFUNCTION("""COMPUTED_VALUE"""),291.34999999999997) -> 291.35 | J34: 1410
A35: 46078.006 | B35: Agus HONNEY | C35: 15 x ROSIN BAGS PACK X 25 UNIDADES ( 6 CM X 11 CM) MICRAJE 25 | D35: 300 | E35: 59.61 | F35: =IFERROR(__xludf.DUMMYFUNCTION("""COMPUTED_VALUE"""),29.805) -> 29.805 | I35: 300
A36: 46080.706 | B36: Guille UY | C36: 1 x Pivot - Onyx, 2 x Pivot Pine, 1 x Hot knife Pearl, 1 x Hot knife Negro, 1 x Peak - Canyon, 1 x Proxy - Onyx, 1 x Peak Pro 3DXL - Onyx, 1 x Peak Pro 3DXL Chamber - Black, 2 x Adaptador Peak Pro Link, 1 x ROSIN BAGS PACK X 20 UNIDADES ( 5CM X 10 CM) MICRAJE 25 | D36: 1507 | E36: 364.304 | F36: =IFERROR(__xludf.DUMMYFUNCTION("""COMPUTED_VALUE"""),364.304) -> 364.304 | I36: 1507
A37: 46080.707 | B37: Agus HONNEY | C37: 1 x Adaptador Peak Pro Link | D37: 120 | E37: 30.838 | F37: =IFERROR(__xludf.DUMMYFUNCTION("""COMPUTED_VALUE"""),15.418999999999997) -> 15.419 | I37: 120
A38: 46080.817 | B38: leloir ong | C38: 1 x Pivot Pine, 2 x Pivot - Onyx, 1 x Adaptador Peak Pro Link | D38: 450 | E38: 121.618 | F38: =IFERROR(__xludf.DUMMYFUNCTION("""COMPUTED_VALUE"""),121.61800000000001) -> 121.618 | I38: 450
A39: 46080.844 | B39: Nahu La Comarca | C39: 2 x Pivot - Onyx, 2 x Pivot Pine, 2 x Hot knife Negro, 1 x Peak - Pine, 1 x Peak - Onyx, 1 x Peak Pro 3DXL - Onyx | D39: 1270 | E39: 302.926 | F39: =IFERROR(__xludf.DUMMYFUNCTION("""COMPUTED_VALUE"""),302.92600000000004) -> 302.926 | J39: 1270
A40: 46080.847 | B40: Nahu La Comarca | C40: 1 x Peak Pro 3D Chamber, 1 x Peak Pro Glass 2.0, 1 x Pivot Mouthpiece 2-Pack , 1 x GLOB MOPS CLASICO | D40: 172 | E40: 53.594 | F40: =IFERROR(__xludf.DUMMYFUNCTION("""COMPUTED_VALUE"""),53.594) -> 53.594 | J40: 172
...

Sheet Control de errores

Sheet Costo Carga
E1: Peso | G1: Costo
A2: Peak Pro 3DXL - Onyx | B2: 18 | C2: 268 | D2: =C2*B2 -> 4824 | E2: 0.791 | F2: =38*E2 -> 30.058 | G2: =F2+C2 -> 298.058
A3: Peak Pro 3DXL - Pearl | B3: 18 | C3: 250 | D3: =C3*B3 -> 4500 | E3: 0.791 | F3: =38*E3 -> 30.058 | G3: =F3+C3 -> 280.058
A4: Proxy - Haze | B4: 24 | C4: 135 | D4: =C4*B4 -> 3240 | E4: 0.566 | F4: =38*E4 -> 21.508 | G4: =F4+C4 -> 156.508
A5: Proxy - Onyx | B5: 24 | C5: 135 | D5: =C5*B5 -> 3240 | E5: 0.566 | F5: =38*E5 -> 21.508 | G5: =F5+C5 -> 156.508
A6: Pivot Pine | B6: 24 | C6: 71 | D6: =C6*B6 -> 1704 | E6: 0.23 | F6: =38*E6 -> 8.74 | G6: =F6+C6 -> 79.74
A7: Pivot - Onyx | B7: 24 | C7: 71 | D7: =C7*B7 -> 1704 | E7: 0.23 | F7: =38*E7 -> 8.74 | G7: =F7+C7 -> 79.74
A8: Peak Pine | B8: 18 | C8: 119 | D8: =C8*B8 -> 2142 | E8: 0.676 | F8: =38*E8 -> 25.688 | G8: =F8+C8 -> 144.688
A9: Peak - Canyon | B9: 18 | C9: 119 | D9: =C9*B9 -> 2142 | E9: 0.676 | F9: =38*E9 -> 25.688 | G9: =F9+C9 -> 144.688
A10: Peak - Onyx | B10: 12 | C10: 119 | D10: =C10*B10 -> 1428 | E10: 0.676 | F10: =38*E10 -> 25.688 | G10: =F10+C10 -> 144.688
A11: Peak Pro 3DXL Chamber - Black | B11: 30 | C11: 50 | D11: =C11*B11 -> 1500 | E11: 0.084 | F11: =38*E11 -> 3.192 | G11: =F11+C11 -> 53.192
A12: Hot knife Negro | B12: 30 | C12: 32.5 | D12: =C12*B12 -> 975 | E12: 0.18 | F12: =38*E12 -> 6.84 | G12: =F12+C12 -> 39.34
A13: Hot knife Pearl | B13: 30 | C13: 32.5 | D13: =C13*B13 -> 975 | E13: 0.18 | F13: =38*E13 -> 6.84 | G13: =F13+C13 -> 39.34
... A22: Peak Atomizer | B22: 12 | C22: 17.5 | D22: =C22*B22 -> 210 | E22: 0.114 | F22: =38*E22 -> 4.332 | G22: =F22+C22 -> 21.832
A23: Adaptador Peak Pro Link | B23: 18 | C23: 74 | D23: =C23*B23 -> 1332 | E23: 0.399 | F23: =38*E23 -> 15.162 | G23: =F23+C23 -> 89.162 | I23: =E23*18 -> 7.182 | J23: 24 | K23: Pro link
D25: =SUM(D2:D23) -> 34671 | F25: =SUM(F2:F23) -> 260.338
A27: ROSIN BAGS PACK X 20 UNIDADES ( 5CM X 10 CM) MICRAJE 25 | B27: 80 | C27: 11 | D27: =C27*B27 -> 880 | E27: 0.027 | F27: =38*E27 -> 1.026 | G27: =F27+C27 -> 12.026 | I27: =E27*80 -> 2.16
A28: ROSIN BAGS PACK X 25 UNIDADES ( 6 CM X 11 CM) MICRAJE 25 | B28: 20 | C28: 15 | D28: =C28*B28 -> 300 | E28: 0.027 | F28: =38*E28 -> 1.026 | G28: =F28+C28 -> 16.026 | I28: =E28*B28 -> 0.54
A29: MALLAS PARA BUBBLE HASH 20 LITROS PACK x 8 unidades | B29: 5 | C29: 203 | D29: =C29*B29 -> 1015 | E29: 0.56 | F29: =38*E29 -> 21.28 | G29: =F29+C29 -> 224.28 | I29: =E29*B29 -> 2.8
D31: =SUM(D27:D29) -> 2195 | I31: =SUM(I23:I29) -> 12.682
A34: Artículo | B34: 12 | C34: $119 | D34: $1,428
A35: Peak Onyx | B35: 12 | C35: $71 | D35: $852
A36: Pivot Pine | B36: 12 | C36: $71 | D36: $852
A37: Pivot Onyx | B37: 30 | C37: $25,50 | D37: $765
A38: Plus Battery - Pearl | B38: 6 | C38: $53,50 | D38: $321
A39: Proxy Bub - Haze | B39: 6 | C39: $53,50 | D39: $321
A40: Proxy Bub - Onyx | B40: 24 | C40: $74 | D40: $1,776
A41: Peak Pro Link - Onyx | B41: 120 | C41: $4,50 | D41: $540
A42: Plus Supercharger
D43: =SUM(D34:D41) -> 0
A46: ITEM | B46: SKU | C46: PRECIO_UNIT | D46: CANTIDAD | E46: TOTAL_PRECIO | F46: PESO_UNIT_ESTIMADO_KG | G46: PESO | H46: KG USD
A47: BigFun! Puffco Pivot Tops - Drei | B47: BF-PA-PVTOPS-DRDL | C47: 15 | D47: 3 | E47: 45 | F47: 0.025 | G47: =F47*D47 -> 0.075 | H47: =F47*38 -> 0.95 | I47: =H47+C47 -> 15.95
A48: BigFun! Puffco Pivot Tops - LIL' Frosty | B48: BF-PA-PVTOPS-SNWMN | C48: 18 | D48: 3 | E48: 54 | F48: 0.02 | G48: =F48*D48 -> 0.06 | H48: =F48*38 -> 0.76 | I48: =H48+C48 -> 18.76
A49: BigFun! Puffco Pivot Tops - LIL' X | B49: BF-PA-PVTOPS-XMAS | C49: 21 | D49: 3 | E49: 63 | F49: 0.031 | G49: =F49*D49 -> 0.093 | H49: =F49*38 -> 1.178 | I49: =H49+C49 -> 22.178
A50: Peak Pro 3DXL Joystick Caps - Black Nebula | B50: EMPIRE-CC-PKPR3DXLJYSTKCPS-BLKNBLS | C50: 10 | D50: 2 | E50: 20 | F50: 0.001 | G50: =F50*D50 -> 0.002 | H50: =F50*38 -> 0.038 | I50: =H50+C50 -> 10.038
A51: Peak Pro 3DXL Joystick Caps Blue Lagoon | B51: EMPIRECC--PKPR3DXLJYSTKCPS-BLULGN | C51: 10 | D51: 2 | E51: 20 | F51: 0.001 | G51: =F51*D51 -> 0.002 | H51: =F51*38 -> 0.038 | I51: =H51+C51 -> 10.038
A52: Peak Pro 3DXL Joystick Caps - Clear | B52: EMPIRECC--PKPR3DXLJYSTKCPS-CLR | C52: 6 | D52: 2 | E52: 12 | F52: 0.001 | G52: =F52*D52 -> 0.002 | H52: =F52*38 -> 0.038 | I52: =H52+C52 -> 6.038
A53: Peak Pro 3DXL Joystick Caps - Eclipse | B53: EMPIRE-CC-PKPR3DXLJYSTKCPS-ECLPS | C53: 10 | D53: 2 | E53: 20 | F53: 0.001 | G53: =F53*D53 -> 0.002 | H53: =F53*38 -> 0.038 | I53: =H53+C53 -> 10.038
A54: Peak Pro 3DXL Joystick Caps - Firestone Red | B54: EMPIRE-CC-PKPR3DXLJYSTKCPS-FRSTNRD | C54: 10 | D54: 2 | E54: 20 | F54: 0.001 | G54: =F54*D54 -> 0.002 | H54: =F54*38 -> 0.038 | I54: =H54+C54 -> 10.038
A55: Peak Pro 3DXL Joystick Caps Glow in the Dark | B55: EMPIRE-CC-PKPR3DXLJYSTKCPS-GITD | C55: 10 | D55: 2 | E55: 20 | F55: 0.001 | G55: =F55*D55 -> 0.002 | H55: =F55*38 -> 0.038 | I55: =H55+C55 -> 10.038
...

Sheet PESOS
A1: Peak Pro 3DXL - Onyx | B1: 0.791
A2: Peak Pro 3DXL - Pearl | B2: 0.791
A3: Proxy - Haze | B3: 0.566
A4: Proxy - Onyx | B4: 0.566
A5: Pivot Pine | B5: 0.23
A6: Pivot - Onyx | B6: 0.23
A7: Peak Pine | B7: 0.676
A8: Peak - Canyon | B8: 0.676
A9: Peak - Onyx | B9: 0.676
A10: Peak Pro 3DXL Chamber - Black | B10: 0.084
A11: Hot knife Negro | B11: 0.18
A12: Hot knife Pearl | B12: 0.18
... A175: Ursa Mini Dab Rig - Clear | B175: 0.262

Sheet COMPRAS Proveedores
A1: fecha | B1: Pedido | C1: Inversion inicial | D1: GEr | E1: Luke | F1: Monto fc | H1: PAGO A CUENTA CON EL COLO | I1: Fee COLO POR GIRO | J1: KG SIXTAR | N1: fecha | O1: USD
A2: 46062 | D2: 6750 | E2: 6750 | M2: GER PLANTO
B3: puffco | F3: $26,436.00 | G3: pedido iniicial | J3: 4940 | M3: FACU LP
B4: puffco | F4: $7,911.00 | G4: pedido post polaco | M4: ONG HIGH UP
A5: 46063 | B5: mallas THE PRESS CLUB | F5: 2150 | G5: mallas para prensar | J5: 304 | M5: Vendedor Tincho
A6: 46066 | B6: MJA | F6: $2,424.91 | G6: bongs de vidrio | H6: 2424.91 | J6: 532 | M6: Vendedor Agustin
A7: 46063 | B7: puffco | F7: 1776 | G7: pro lin reestock | M7: COCO SALTA 420
A8: 46066 | B8: puffco | F8: $6,315.00 | G8: reestock pivot peak link | J8: 304 | M8: BIG FACU COSTA ATLANTICA
B9: Mininail | F9: 3118.78 | H9: 3118.78 | M9: CHARLY DISTRI
B10: Glob Mops
B11: Formula 420 | F11: 2973.81
B12: papel reynols amazon luke | F12: 353 | J12: 275 | L12: pago luke con TC
B13: Ryanfit Glass pivot | F13: 253 | H13: 253 | L13: pago colo con TC
B14: puffco | F14: 540
B15: puffco | F15: 16116
B16: mallas THE PRESS CLUB reestock | F16: 2710
B17: MJA reestock | F17: 3497.5
B18: puffco producto nuevo | F18: 10470

Sheet Cta Cte total
A1: FECHA INGRESO | B1: SOCIO (Lucas/German) | C1: MONTO PUESTO | E1: FECHA GASTO | F1: DETALLE (Qué se pagó) | G1: MONTO GASTADO | I1: FECHA | J1: MOVIMIENTO | K1: ENTRADA | L1: SALIDA | M1: SALDO EN CAJA
A2: 46062 | B2: Lucas | C2: 6750 | E2: 46063 | F2: Sixstar Puffco 1 | G2: 4940 | I2: =IFERROR(__xludf.DUMMYFUNCTION("SORT(FILTER(VSTACK( IFNA(FILTER(HSTACK(A2:A1000, ""Ingreso: ""&B2:B1000, C2:C1000, IF(ROW(A2:A1000),0)), (A2:A1000<>"""")+(B2:B1000<>"""")+(C2:C1000<>"""")), HSTACK("""","""",0,0)), IFNA(FILTER(HSTACK(E2:E1000, ""Gasto: ""&F2:F1000, IF(ROW(E2:E1000)"&",0), G2:G1000), (E2:E1000<>"""")+(F2:F1000<>"""")+(G2:G1000<>"""")), HSTACK("""","""",0,0)), IFNA(FILTER(HSTACK('CTA CTE COLO'!B2:B1000, ""Colo: ""&'CTA CTE COLO'!A2:A1000, IF('CTA CTE COLO'!F2:F1000>0, 'CTA CTE COLO'!F2:F1000, 0), IF('CTA CTE COLO'!F2"&":F1000<0, ABS('CTA CTE COLO'!F2:F1000), 0)), ISNUMBER('CTA CTE COLO'!F2:F1000)*('CTA CTE COLO'!F2:F1000<>0)), HSTACK("""","""",0,0)) ), INDEX(VSTACK( IFNA(FILTER(A2:A1000, (A2:A1000<>"""")+(B2:B1000<>"""")+(C2:C1000<>"""")), """"), IFNA(FILTER(E2:E1"&"000, (E2:E1000<>"""")+(F2:F1000<>"""")+(G2:G1000<>"""")), """"), IFNA(FILTER('CTA CTE COLO'!B2:B1000, ISNUMBER('CTA CTE COLO'!F2:F1000)*('CTA CTE COLO'!F2:F1000<>0)), """") ), 0, 1)<>""""), 1, TRUE)"),46032.0) -> 46032 | J2: =IFERROR(__xludf.DUMMYFUNCTION("""COMPUTED_VALUE"""),"Colo: ANTERIOR") -> Colo: ANTERIOR | K2: =IFERROR(__xludf.DUMMYFUNCTION("""COMPUTED_VALUE"""),1158.0) -> 1158 | L2: =IFERROR(__xludf.DUMMYFUNCTION("""COMPUTED_VALUE"""),0.0) -> 0 | M2: {=IF(I2:I1000="", "", SCAN(0, N(K2:K1000) - N(L2:L1000), LAMBDA(acumulado, diferencia, acumulado + diferencia)))} -> 1158
A3: 46062 | B3: German | C3: 6750 | E3: 46063 | F3: Sixstar Press club | G3: 304 | I3: =IFERROR(__xludf.DUMMYFUNCTION("""COMPUTED_VALUE"""),46053.0) -> 46053 | J3: =IFERROR(__xludf.DUMMYFUNCTION("""COMPUTED_VALUE"""),"Colo: The press Club") -> Colo: The press Club | K3: =IFERROR(__xludf.DUMMYFUNCTION("""COMPUTED_VALUE"""),0.0) -> 0 | L3: =IFERROR(__xludf.DUMMYFUNCTION("""COMPUTED_VALUE"""),2180.0) -> 2180 | M3: -1022
E4: 46065 | F4: Sixstar Puffco 2 | G4: 304 | I4: =IFERROR(__xludf.DUMMYFUNCTION("""COMPUTED_VALUE"""),46058.0) -> 46058 | J4: =IFERROR(__xludf.DUMMYFUNCTION("""COMPUTED_VALUE"""),"Colo: ANTERIOR") -> Colo: ANTERIOR | K4: =IFERROR(__xludf.DUMMYFUNCTION("""COMPUTED_VALUE"""),386.0) -> 386 | L4: =IFERROR(__xludf.DUMMYFUNCTION("""COMPUTED_VALUE"""),0.0) -> 0 | M4: -636
E5: 46065 | F5: Sixstar Reynols | G5: 275 | I5: =IFERROR(__xludf.DUMMYFUNCTION("""COMPUTED_VALUE"""),46062.0) -> 46062 | J5: =IFERROR(__xludf.DUMMYFUNCTION("""COMPUTED_VALUE"""),"Ingreso: Lucas") -> Ingreso: Lucas | K5: =IFERROR(__xludf.DUMMYFUNCTION("""COMPUTED_VALUE"""),6750.0) -> 6750 | L5: =IFERROR(__xludf.DUMMYFUNCTION("""COMPUTED_VALUE"""),0.0) -> 0 | M5: 6114
E6: 46080 | F6: Sixstar Puffco 3 | G6: 1216 | I6: =IFERROR(__xludf.DUMMYFUNCTION("""COMPUTED_VALUE"""),46062.0) -> 46062 | J6: =IFERROR(__xludf.DUMMYFUNCTION("""COMPUTED_VALUE"""),"Ingreso: German") -> Ingreso: German | K6: =IFERROR(__xludf.DUMMYFUNCTION("""COMPUTED_VALUE"""),6750.0) -> 6750 | L6: =IFERROR(__xludf.DUMMYFUNCTION("""COMPUTED_VALUE"""),0.0) -> 0 | M6: 12864
E7: 46083 | F7: Sixstar MJ ARSENAL | G7: 532 | I7: =IFERROR(__xludf.DUMMYFUNCTION("""COMPUTED_VALUE"""),46063.0) -> 46063 | J7: =IFERROR(__xludf.DUMMYFUNCTION("""COMPUTED_VALUE"""),"Gasto: Sixstar Puffco 1") -> Gasto: Sixstar Puffco 1 | K7: =IFERROR(__xludf.DUMMYFUNCTION("""COMPUTED_VALUE"""),0.0) -> 0 | L7: =IFERROR(__xludf.DUMMYFUNCTION("""COMPUTED_VALUE"""),4940.0) -> 4940 | M7: 7924
E8: 46090 | F8: Sixstar Mininail/bubble | G8: 4750 | I8: =IFERROR(__xludf.DUMMYFUNCTION("""COMPUTED_VALUE"""),46063.0) -> 46063 | J8: =IFERROR(__xludf.DUMMYFUNCTION("""COMPUTED_VALUE"""),"Gasto: Sixstar Press club") -> Gasto: Sixstar Press club | K8: =IFERROR(__xludf.DUMMYFUNCTION("""COMPUTED_VALUE"""),0.0) -> 0 | L8: =IFERROR(__xludf.DUMMYFUNCTION("""COMPUTED_VALUE"""),304.0) -> 304 | M8: 7620
E9: 46091 | F9: Sixstar puffco 4 | G9: 2546 | I9: =IFERROR(__xludf.DUMMYFUNCTION("""COMPUTED_VALUE"""),46064.0) -> 46064 | J9: =IFERROR(__xludf.DUMMYFUNCTION("""COMPUTED_VALUE"""),"Colo: PAGO PUFFCO") -> Colo: PAGO PUFFCO | K9: =IFERROR(__xludf.DUMMYFUNCTION("""COMPUTED_VALUE"""),0.0) -> 0 | L9: =IFERROR(__xludf.DUMMYFUNCTION("""COMPUTED_VALUE"""),4162.0) -> 4162 | M9: 3458
E10: 46086 | F10: Nacho | G10: 282.69 | I10: =IFERROR(__xludf.DUMMYFUNCTION("""COMPUTED_VALUE"""),46064.0) -> 46064 | J10: =IFERROR(__xludf.DUMMYFUNCTION("""COMPUTED_VALUE"""),"Colo: INGRESO LUCAS") -> Colo: INGRESO LUCAS | K10: =IFERROR(__xludf.DUMMYFUNCTION("""COMPUTED_VALUE"""),4000.0) -> 4000 | L10: =IFERROR(__xludf.DUMMYFUNCTION("""COMPUTED_VALUE"""),0.0) -> 0 | M10: 7458
E11: 46086 | F11: Coca | G11: 240.28 | I11: =IFERROR(__xludf.DUMMYFUNCTION("""COMPUTED_VALUE"""),46065.0) -> 46065 | J11: =IFERROR(__xludf.DUMMYFUNCTION("""COMPUTED_VALUE"""),"Gasto: Sixstar Puffco 2") -> Gasto: Sixstar Puffco 2 | K11: =IFERROR(__xludf.DUMMYFUNCTION("""COMPUTED_VALUE"""),0.0) -> 0 | L11: =IFERROR(__xludf.DUMMYFUNCTION("""COMPUTED_VALUE"""),304.0) -> 304 | M11: 7154
E12: 46094 | F12: Sistar puffco 5 (proxy core) | G12: 1140 | I12: =IFERROR(__xludf.DUMMYFUNCTION("""COMPUTED_VALUE"""),46065.0) -> 46065 | J12: =IFERROR(__xludf.DUMMYFUNCTION("""COMPUTED_VALUE"""),"Gasto: Sixstar Reynols") -> Gasto: Sixstar Reynols | K12: =IFERROR(__xludf.DUMMYFUNCTION("""COMPUTED_VALUE"""),0.0) -> 0 | L12: =IFERROR(__xludf.DUMMYFUNCTION("""COMPUTED_VALUE"""),275.0) -> 275 | M12: 6879 | O12: Le di 300 dls que habia dejado FACU LP para completar el retiro
E13: 46099 | F13: nachito al dia | G13: 418 | I13: =IFERROR(__xludf.DUMMYFUNCTION("""COMPUTED_VALUE"""),46067.0) -> 46067 | J13: =IFERROR(__xludf.DUMMYFUNCTION("""COMPUTED_VALUE"""),"Colo: PAGO MEDUSA") -> Colo: PAGO MEDUSA | K13: =IFERROR(__xludf.DUMMYFUNCTION("""COMPUTED_VALUE"""),0.0) -> 0 | L13: =IFERROR(__xludf.DUMMYFUNCTION("""COMPUTED_VALUE"""),2349.0) -> 2349 | M13: 4530 | O13: Le di pesos que dejo Marshal
E14: 46100 | F14: reserva oficina Leloir | G14: 400 | I14: =IFERROR(__xludf.DUMMYFUNCTION("""COMPUTED_VALUE"""),46070.0) -> 46070 | J14: =IFERROR(__xludf.DUMMYFUNCTION("""COMPUTED_VALUE"""),"Colo: Facundo Millan") -> Colo: Facundo Millan | K14: =IFERROR(__xludf.DUMMYFUNCTION("""COMPUTED_VALUE"""),4542.0) -> 4542 | L14: =IFERROR(__xludf.DUMMYFUNCTION("""COMPUTED_VALUE"""),0.0) -> 0 | M14: 9072 | O14: le di dolares que dejo Marshal
E15: 46101 | F15: Sixstar MJ ARSENAL 2 29kg | G15: 1102 | I15: =IFERROR(__xludf.DUMMYFUNCTION("""COMPUTED_VALUE"""),46071.0) -> 46071 | J15: =IFERROR(__xludf.DUMMYFUNCTION("""COMPUTED_VALUE"""),"Colo: PAGO MININAIL") -> Colo: PAGO MININAIL | K15: =IFERROR(__xludf.DUMMYFUNCTION("""COMPUTED_VALUE"""),0.0) -> 0 | L15: =IFERROR(__xludf.DUMMYFUNCTION("""COMPUTED_VALUE"""),3043.0) -> 3043 | M15: 6029 | O15: le di a nachito resto de Marshal y y Social club 428 sobran en EFT USD 177
E16: 46105 | F16: pago bolsas la despensa | G16: 120 | I16: =IFERROR(__xludf.DUMMYFUNCTION("""COMPUTED_VALUE"""),46072.0) -> 46072 | J16: =IFERROR(__xludf.DUMMYFUNCTION("""COMPUTED_VALUE"""),"Colo: Nachito") -> Colo: Nachito | K16: =IFERROR(__xludf.DUMMYFUNCTION("""COMPUTED_VALUE"""),694.0) -> 694 | L16: =IFERROR(__xludf.DUMMYFUNCTION("""COMPUTED_VALUE"""),0.0) -> 0 | M16: 6723 | O16: de los 177 use 120 para el pago de bolsas $187500 sobran USD 57
E17: 46111 | F17: Sixtar puffco 6 (pro proxy) 64,5kg | G17: 2451 | I17: =IFERROR(__xludf.DUMMYFUNCTION("""COMPUTED_VALUE"""),46072.0) -> 46072 | J17: =IFERROR(__xludf.DUMMYFUNCTION("""COMPUTED_VALUE"""),"Colo: Nachito") -> Colo: Nachito | K17: =IFERROR(__xludf.DUMMYFUNCTION("""COMPUTED_VALUE"""),1740.0) -> 1740 | L17: =IFERROR(__xludf.DUMMYFUNCTION("""COMPUTED_VALUE"""),0.0) -> 0 | M17: 8463 | O17: 2000 de eft de Tincho UY + 300 marshal 1-4 + 151 cambio
E18: 46114 | F18: oficina leloir (deposito 500 + honorarios 570+ alquiler 50dls (400 fueron de reserva) | G18: 1209 | I18: =IFERROR(__xludf.DUMMYFUNCTION("""COMPUTED_VALUE"""),46072.0) -> 46072 | J18: =IFERROR(__xludf.DUMMYFUNCTION("""COMPUTED_VALUE"""),"Colo: PAGO REYNOLS") -> Colo: PAGO REYNOLS | K18: =IFERROR(__xludf.DUMMYFUNCTION("""COMPUTED_VALUE"""),0.0) -> 0 | L18: =IFERROR(__xludf.DUMMYFUNCTION("""COMPUTED_VALUE"""),304.0) -> 304 | M18: 8159 | O18: 1840 de eft de Tincho sobran USD 631
E19: 46127 | F19: puffco 7 (core + hot +acc) 14kg | G19: 532 | I19: =IFERROR(__xludf.DUMMYFUNCTION("""COMPUTED_VALUE"""),46072.0) -> 46072 | J19: =IFERROR(__xludf.DUMMYFUNCTION("""COMPUTED_VALUE"""),"Colo: CARGO POR USD") -> Colo: CARGO POR USD | K19: =IFERROR(__xludf.DUMMYFUNCTION("""COMPUTED_VALUE"""),0.0) -> 0 | L19: =IFERROR(__xludf.DUMMYFUNCTION("""COMPUTED_VALUE"""),35.0) -> 35 | M19: 8124
E20: 46127 | F20: mallas press club 16,5 kg | G20: 627 | I20: =IFERROR(__xludf.DUMMYFUNCTION("""COMPUTED_VALUE"""),46072.0) -> 46072 | J20: =IFERROR(__xludf.DUMMYFUNCTION("""COMPUTED_VALUE"""),"Colo: Nachito") -> Colo: Nachito | K20: =IFERROR(__xludf.DUMMYFUNCTION("""COMPUTED_VALUE"""),5900.0) -> 5900 | L20: =IFERROR(__xludf.DUMMYFUNCTION("""COMPUTED_VALUE"""),0.0) -> 0 | M20: 14024
E21: 46128 | F21: nachito al dia | G21: 400 | I21: =IFERROR(__xludf.DUMMYFUNCTION("""COMPUTED_VALUE"""),46075.0) -> 46075 | J21: =IFERROR(__xludf.DUMMYFUNCTION("""COMPUTED_VALUE"""),"Colo: Abril Barbaria") -> Colo: Abril Barbaria | K21: =IFERROR(__xludf.DUMMYFUNCTION("""COMPUTED_VALUE"""),3001.0) -> 3001 | L21: =IFERROR(__xludf.DUMMYFUNCTION("""COMPUTED_VALUE"""),0.0) -> 0 | M21: 17025
E22: 46128 | F22: Puesta a punto oficina insumos electricidad LED | G22: 320 | I22: =IFERROR(__xludf.DUMMYFUNCTION("""COMPUTED_VALUE"""),46077.0) -> 46077 | J22: =IFERROR(__xludf.DUMMYFUNCTION("""COMPUTED_VALUE"""),"Colo: PAGO PUFCO") -> Colo: PAGO PUFCO | K22: =IFERROR(__xludf.DUMMYFUNCTION("""COMPUTED_VALUE"""),0.0) -> 0 | L22: =IFERROR(__xludf.DUMMYFUNCTION("""COMPUTED_VALUE"""),7190.0) -> 7190 | M22: 9835
E23: 46134 | F23: puffco 8 (proxy v2, pro hot | G23: 874 | I23: =IFERROR(__xludf.DUMMYFUNCTION("""COMPUTED_VALUE"""),46077.0) -> 46077 | J23: =IFERROR(__xludf.DUMMYFUNCTION("""COMPUTED_VALUE"""),"Colo: PAGO TIN UY") -> Colo: PAGO TIN UY | K23: =IFERROR(__xludf.DUMMYFUNCTION("""COMPUTED_VALUE"""),2000.0) -> 2000 | L23: =IFERROR(__xludf.DUMMYFUNCTION("""COMPUTED_VALUE"""),0.0) -> 0 | M23: 11835
E24: 46148 | F24: cortinas oficina | G24: 478 | I24: =IFERROR(__xludf.DUMMYFUNCTION("""COMPUTED_VALUE"""),46077.0) -> 46077 | J24: =IFERROR(__xludf.DUMMYFUNCTION("""COMPUTED_VALUE"""),"Colo: BUBBLE BAG") -> Colo: BUBBLE BAG | K24: =IFERROR(__xludf.DUMMYFUNCTION("""COMPUTED_VALUE"""),0.0) -> 0 | L24: =IFERROR(__xludf.DUMMYFUNCTION("""COMPUTED_VALUE"""),3243.0) -> 3243 | M24: 8592 | O24: se abono con parte de pedido de maldita tangie
E25: 46148 | F25: coca abril y mayo | G25: 485 | I25: =IFERROR(__xludf.DUMMYFUNCTION("""COMPUTED_VALUE"""),46077.0) -> 46077 | J25: =IFERROR(__xludf.DUMMYFUNCTION("""COMPUTED_VALUE"""),"Colo: Formula 420") -> Colo: Formula 420 | K25: =IFERROR(__xludf.DUMMYFUNCTION("""COMPUTED_VALUE"""),0.0) -> 0 | L25: =IFERROR(__xludf.DUMMYFUNCTION("""COMPUTED_VALUE"""),3048.0) -> 3048 | M25: 5544
E26: 46151 | F26: nachito al dia | G26: 470 | I26: =IFERROR(__xludf.DUMMYFUNCTION("""COMPUTED_VALUE"""),46077.0) -> 46077 | J26: =IFERROR(__xludf.DUMMYFUNCTION("""COMPUTED_VALUE"""),"Colo: The press club") -> Colo: The press club | K26: =IFERROR(__xludf.DUMMYFUNCTION("""COMPUTED_VALUE"""),0.0) -> 0 | L26: =IFERROR(__xludf.DUMMYFUNCTION("""COMPUTED_VALUE"""),2785.0) -> 2785 | M26: 2759
E27: 46153 | F27: Alquiler Mayo y Junio | G27: 900 | I27: =IFERROR(__xludf.DUMMYFUNCTION("""COMPUTED_VALUE"""),46077.0) -> 46077 | J27: =IFERROR(__xludf.DUMMYFUNCTION("""COMPUTED_VALUE"""),"Colo: Formula 420") -> Colo: Formula 420 | K27: =IFERROR(__xludf.DUMMYFUNCTION("""COMPUTED_VALUE"""),0.0) -> 0 | L27: =IFERROR(__xludf.DUMMYFUNCTION("""COMPUTED_VALUE"""),3572.0) -> 3572 | M27: -813
E28: 46153 | F28: expensas e impuestos ver | G28: 230 | I28: =IFERROR(__xludf.DUMMYFUNCTION("""COMPUTED_VALUE"""),46078.0) -> 46078 | J28: =IFERROR(__xludf.DUMMYFUNCTION("""COMPUTED_VALUE"""),"Colo: Rodrigo Orellano") -> Colo: Rodrigo Orellano | K28: =IFERROR(__xludf.DUMMYFUNCTION("""COMPUTED_VALUE"""),1481.0) -> 1481 | L28: =IFERROR(__xludf.DUMMYFUNCTION("""COMPUTED_VALUE"""),0.0) -> 0 | M28: 668
E29: 46157 | F29: puffco 9 reestoc 46kg | G29: 1748 | I29: =IFERROR(__xludf.DUMMYFUNCTION("""COMPUTED_VALUE"""),46080.0) -> 46080 | J29: =IFERROR(__xludf.DUMMYFUNCTION("""COMPUTED_VALUE"""),"Gasto: Sixstar Puffco 3") -> Gasto: Sixstar Puffco 3 | K29: =IFERROR(__xludf.DUMMYFUNCTION("""COMPUTED_VALUE"""),0.0) -> 0 | L29: =IFERROR(__xludf.DUMMYFUNCTION("""COMPUTED_VALUE"""),1216.0) -> 1216 | M29: -548
E30: 46161 | F30: puffco 10 producto nuevo 93kg | G30: 3534 | I30: =IFERROR(__xludf.DUMMYFUNCTION("""COMPUTED_VALUE"""),46080.0) -> 46080 | J30: =IFERROR(__xludf.DUMMYFUNCTION("""COMPUTED_VALUE"""),"Colo: Nuñez Agustin") -> Colo: Nuñez Agustin | K30: =IFERROR(__xludf.DUMMYFUNCTION("""COMPUTED_VALUE"""),609.0) -> 609 | L30: =IFERROR(__xludf.DUMMYFUNCTION("""COMPUTED_VALUE"""),0.0) -> 0 | M30: 61
E31: 46176 | F31: retirar holanda 134kg + 57kg vol | G31: 6720 | I31: =IFERROR(__xludf.DUMMYFUNCTION("""COMPUTED_VALUE"""),46083.0) -> 46083 | J31: =IFERROR(__xludf.DUMMYFUNCTION("""COMPUTED_VALUE"""),"Gasto: Sixstar MJ ARSENAL") -> Gasto: Sixstar MJ ARSENAL | K31: =IFERROR(__xludf.DUMMYFUNCTION("""COMPUTED_VALUE"""),0.0) -> 0 | L31: =IFERROR(__xludf.DUMMYFUNCTION("""COMPUTED_VALUE"""),532.0) -> 532 | M31: -471
E32: 46181 | F32: MJA vidrios 3 usa 23kg | G32: 874 | I32: =IFERROR(__xludf.DUMMYFUNCTION("""COMPUTED_VALUE"""),46086.0) -> 46086 | J32: =IFERROR(__xludf.DUMMYFUNCTION("""COMPUTED_VALUE"""),"Gasto: Nacho") -> Gasto: Nacho | K32: =IFERROR(__xludf.DUMMYFUNCTION("""COMPUTED_VALUE"""),0.0) -> 0 | L32: =IFERROR(__xludf.DUMMYFUNCTION("""COMPUTED_VALUE"""),282.69) -> 282.69 | M32: -753.69
E33: 46182 | F33: puffco 11 pivot knife 27,5 | G33: 1045 | I33: =IFERROR(__xludf.DUMMYFUNCTION("""COMPUTED_VALUE"""),46086.0) -> 46086 | J33: =IFERROR(__xludf.DUMMYFUNCTION("""COMPUTED_VALUE"""),"Gasto: Coca") -> Gasto: Coca | K33: =IFERROR(__xludf.DUMMYFUNCTION("""COMPUTED_VALUE"""),0.0) -> 0 | L33: =IFERROR(__xludf.DUMMYFUNCTION("""COMPUTED_VALUE"""),240.28) -> 240.28 | M33: -993.97
E34: 46191 | F34: edenor, municipal ofi | G34: 200 | I34: =IFERROR(__xludf.DUMMYFUNCTION("""COMPUTED_VALUE"""),46087.0) -> 46087 | J34: =IFERROR(__xludf.DUMMYFUNCTION("""COMPUTED_VALUE"""),"Colo: Barbaria Abril") -> Colo: Barbaria Abril | K34: =IFERROR(__xludf.DUMMYFUNCTION("""COMPUTED_VALUE"""),1786.0) -> 1786 | L34: =IFERROR(__xludf.DUMMYFUNCTION("""COMPUTED_VALUE"""),0.0) -> 0 | M34: 792.03
E35: 46192 | F35: coca junio | G35: 235 | I35: =IFERROR(__xludf.DUMMYFUNCTION("""COMPUTED_VALUE"""),46090.0) -> 46090 | J35: =IFERROR(__xludf.DUMMYFUNCTION("""COMPUTED_VALUE"""),"Gasto: Sixstar Mininail/bubble") -> Gasto: Sixstar Mininail/bubble | K35: =IFERROR(__xludf.DUMMYFUNCTION("""COMPUTED_VALUE"""),0.0) -> 0 | L35: =IFERROR(__xludf.DUMMYFUNCTION("""COMPUTED_VALUE"""),4750.0) -> 4750 | M35: -3957.97
E36: 46192 | F36: nachito | G36: 340 | I36: =IFERROR(__xludf.DUMMYFUNCTION("""COMPUTED_VALUE"""),46091.0) -> 46091 | J36: =IFERROR(__xludf.DUMMYFUNCTION("""COMPUTED_VALUE"""),"Gasto: Sixstar puffco 4") -> Gasto: Sixstar puffco 4 | K36: =IFERROR(__xludf.DUMMYFUNCTION("""COMPUTED_VALUE"""),0.0) -> 0 | L36: =IFERROR(__xludf.DUMMYFUNCTION("""COMPUTED_VALUE"""),2546.0) -> 2546 | M36: -6503.97
E37: 46202 | F37: puffco 12 71kg | G37: 2698 | I37: =IFERROR(__xludf.DUMMYFUNCTION("""COMPUTED_VALUE"""),46093.0) -> 46093 | J37: =IFERROR(__xludf.DUMMYFUNCTION("""COMPUTED_VALUE"""),"Colo: Nachito") -> Colo: Nachito | K37: =IFERROR(__xludf.DUMMYFUNCTION("""COMPUTED_VALUE"""),3680.0) -> 3680 | L37: =IFERROR(__xludf.DUMMYFUNCTION("""COMPUTED_VALUE"""),0.0) -> 0 | M37: -2823.97
E38: 46205 | F38: bolsas la despensa | G38: 240 | I38: =IFERROR(__xludf.DUMMYFUNCTION("""COMPUTED_VALUE"""),46094.0) -> 46094 | J38: =IFERROR(__xludf.DUMMYFUNCTION("""COMPUTED_VALUE"""),"Gasto: Sistar puffco 5 (proxy core)") -> Gasto: Sistar puffco 5 (proxy core) | K38: =IFERROR(__xludf.DUMMYFUNCTION("""COMPUTED_VALUE"""),0.0) -> 0 | L38: =IFERROR(__xludf.DUMMYFUNCTION("""COMPUTED_VALUE"""),1140.0) -> 1140 | M38: -3963.97
E39: 46213 | F39: nacho al dia | G39: 300 | I39: =IFERROR(__xludf.DUMMYFUNCTION("""COMPUTED_VALUE"""),46097.0) -> 46097 | J39: =IFERROR(__xludf.DUMMYFUNCTION("""COMPUTED_VALUE"""),"Colo: Carranza Alejandro") -> Colo: Carranza Alejandro | K39: =IFERROR(__xludf.DUMMYFUNCTION("""COMPUTED_VALUE"""),3215.0) -> 3215 | L39: =IFERROR(__xludf.DUMMYFUNCTION("""COMPUTED_VALUE"""),0.0) -> 0 | M39: -748.97
E40: 46216 | F40: alquiler Julio y aogsto | G40: 900 | I40: =IFERROR(__xludf.DUMMYFUNCTION("""COMPUTED_VALUE"""),46098.0) -> 46098 | J40: =IFERROR(__xludf.DUMMYFUNCTION("""COMPUTED_VALUE"""),"Colo: PAGO PUFCO") -> Colo: PAGO PUFCO | K40: =IFERROR(__xludf.DUMMYFUNCTION("""COMPUTED_VALUE"""),0.0) -> 0 | L40: =IFERROR(__xludf.DUMMYFUNCTION("""COMPUTED_VALUE"""),5175.0) -> 5175 | M40: -5923.97 | O40: 600 de guille naesa + 300 nahu la comarca
...

Sheet CTA CTE COLO
A1: Cliente | B1: Fecha | C1: Pesos | D1: Fee | E1: RECIBIDO | F1: USD | G1: Chequeado | H1: TC
A2: ANTERIOR | B2: 46373 | C2: 165000 | D2: =C2*3.5% -> 5775 | E2: =C2-D2 -> 159225 | G2: x | I2: =SUM(F2:F1077) -> -4353.88
A3: ANTERIOR | B3: 46375 | C3: 163350 | D3: =C3*3.5% -> 5717.25 | E3: =C3-D3 -> 157632.75 | G3: x
A4: ANTERIOR | B4: 46378 | C4: 282150 | D4: =C4*3.5% -> 9875.25 | E4: =C4-D4 -> 272274.75 | G4: x
A5: ANTERIOR | B5: 46378 | C5: 500000 | D5: =C5*3.5% -> 17500 | E5: =C5-D5 -> 482500 | G5: x
A6: ANTERIOR | B6: 46379 | C6: 500000 | D6: =C6*3.5% -> 17500 | E6: =C6-D6 -> 482500 | G6: x
A7: ANTERIOR | B7: 46031 | C7: 75000 | D7: =C7*3.5% -> 2625 | E7: =C7-D7 -> 72375 | G7: x
A8: ANTERIOR | B8: 46032 | C8: 45000 | D8: =C8*3.5% -> 1575 | E8: =C8-D8 -> 43425 | G8: x
A9: ANTERIOR | B9: 46032 | C9: 75000 | D9: =C9*3.5% -> 2625 | E9: =C9-D9 -> 72375 | F9: 1158 | G9: x | H9: 1504.58
A10: The press Club | B10: 46053 | C10: 0 | D10: =C10*3.5% -> 0 | E10: =C10-D10 -> 0 | F10: -2180 | G10: x
A11: ANTERIOR | B11: 46058 | C11: 576000 | D11: =C11*3.5% -> 20160 | E11: =C11-D11 -> 555840 | F11: 386 | G11: x | H11: =E11/F11 -> 1440
A12: PAGO PUFFCO | B12: 46064 | C12: 0 | D12: =C12*3.5% -> 0 | E12: =C12-D12 -> 0 | F12: -4162 | G12: x
A13: ANTERIOR | B13: 46060 | C13: 150000 | D13: =C13*3.5% -> 5250 | E13: =C13-D13 -> 144750 | G13: x
A14: ANTERIOR | B14: 46063 | C14: 7300 | D14: =C14*3.5% -> 255.5 | E14: =C14-D14 -> 7044.5 | G14: x
A15: ANTERIOR | B15: 46063 | C15: 228000 | D15: =C15*3.5% -> 7980 | E15: =C15-D15 -> 220020 | G15: x
A16: INGRESO LUCAS | B16: 46064 | C16: 0 | D16: =C16*3.5% -> 0 | E16: =C16-D16 -> 0 | F16: 4000 | G16: x
A17: ANTERIOR | B17: 46064 | C17: 1988075 | D17: =C17*3.5% -> 69582.625 | E17: =C17-D17 -> 1918492.4 | G17: x
A18: Juan Carlos Morales | B18: 46065 | C18: 1875000 | D18: =C18*3.5% -> 65625 | E18: =C18-D18 -> 1809375 | G18: x
A19: Rodrigo Orellano | B19: 46065 | C19: 215250 | D19: =C19*3.5% -> 7533.75 | E19: =C19-D19 -> 207716.25 | G19: x
A20: Gaston Balsamo | B20: 46065 | C20: 230000 | D20: =C20*3.5% -> 8050 | E20: =C20-D20 -> 221950 | G20: x
A21: Abril Barbaria | B21: 46066 | C21: 430000 | D21: =C21*3.5% -> 15050 | E21: =C21-D21 -> 414950 | G21: x
A22: Facundo Millan | B22: 46066 | C22: 426000 | D22: =C22*3.5% -> 14910 | E22: =C22-D22 -> 411090 | G22: x
A23: Rodrigo Hanun | B23: 46066 | C23: 230400 | D23: =C23*3.5% -> 8064 | E23: =C23-D23 -> 222336 | G23: x
A24: Leandro Lujan | B24: 46066 | C24: 288000 | D24: =C24*3.5% -> 10080 | E24: =C24-D24 -> 277920 | G24: x
A25: Facundo Millan | B25: 46070 | C25: 710000 | D25: =C25*3.5% -> 24850 | E25: =C25-D25 -> 685150 | F25: 4542 | G25: x | H25: =SUM(E13:E25)/F25 -> 1440.0692
A26: PAGO MEDUSA | B26: 46067 | F26: -2349 | G26: x
A27: PAGO MININAIL | B27: 46071 | F27: -3043 | G27: x
A28: Nachito | B28: 46072 | C28: 1000000 | D28: =C28*3.5% -> 35000 | E28: =C28-D28 -> 965000 | F28: 694 | G28: x | H28: =E28/F28 -> 1390.4899
A29: Nachito | B29: 46072 | F29: 1740 | G29: x
A30: PAGO REYNOLS | B30: 46072 | F30: -304 | G30: x
A31: CARGO POR USD | B31: 46072 | F31: -35 | G31: x
A32: Rodrigo Orellano | B32: 46071 | C32: 452000 | D32: =C32*3.5% -> 15820 | E32: =C32-D32 -> 436180 | G32: x
A33: Palomeque Matias | B33: 46072 | C33: 115000 | D33: =C33*3.5% -> 4025 | E33: =C33-D33 -> 110975 | G33: x
A34: Flavio Papa | B34: 46072 | C34: 145000 | D34: =C34*3.5% -> 5075 | E34: =C34-D34 -> 139925 | G34: x
A35: Bosio German | B35: 46072 | C35: 1022400 | D35: =C35*3.5% -> 35784 | E35: =C35-D35 -> 986616 | G35: x
A36: Abril Barbaria | B36: 46072 | C36: 94000 | D36: =C36*3.5% -> 3290 | E36: =C36-D36 -> 90710 | G36: x
A37: Rodrigo Sosa | B37: 46073 | C37: 500000 | D37: =C37*3.5% -> 17500 | E37: =C37-D37 -> 482500 | G37: x
A38: Astrogrow | B38: 46073 | C38: 1591400 | D38: =C38*3.5% -> 55699 | E38: =C38-D38 -> 1535701 | G38: x
A39: Abril Barbaria | B39: 46075 | C39: 543000 | D39: =C39*3.5% -> 19005 | E39: =C39-D39 -> 523995 | F39: 3001 | G39: x | H39: =SUM(E32:E39)/F39 -> 1435.0556
A40: PAGO PUFCO | B40: 46077 | F40: -7190 | G40: x
...

Sheet TIN UY
A1: Fecha | B1: Total de pedido | C1: Comision | D1: a Rendir | E1: Fecha Pago | F1: Pago | H1: SALDO ACTUAL: | I1: =SUM(D2:D1007) - SUM(F2:F1007) -> 10639.221
A2: =IFERROR(__xludf.DUMMYFUNCTION("QUERY(Pedidos!A2:E1007, ""SELECT A, D, (E/2) WHERE lower(B) CONTAINS 'tin uy'"", 0)"),"") | B2: =IFERROR(__xludf.DUMMYFUNCTION("""COMPUTED_VALUE"""),"") | C2: =IFERROR(__xludf.DUMMYFUNCTION("""COMPUTED_VALUE"""),"quotient(2())") -> quotient(2()) | D2: {=IF(B2:B1007="", "", B2:B1007 - C2:C1007)} | E2: 46023 | F2: 0
A3: =IFERROR(__xludf.DUMMYFUNCTION("""COMPUTED_VALUE"""),46065.56648637731) -> 46065.566 | B3: =IFERROR(__xludf.DUMMYFUNCTION("""COMPUTED_VALUE"""),5185.0) -> 5185 | C3: =IFERROR(__xludf.DUMMYFUNCTION("""COMPUTED_VALUE"""),630.0029999999999) -> 630.003 | D3: 4554.997 | E3: 46058 | F3: 400 | H3: 576000 | I3: =H3/F3 -> 1440
A4: =IFERROR(__xludf.DUMMYFUNCTION("""COMPUTED_VALUE"""),46066.48805971065) -> 46066.488 | B4: =IFERROR(__xludf.DUMMYFUNCTION("""COMPUTED_VALUE"""),380.0) -> 380 | C4: =IFERROR(__xludf.DUMMYFUNCTION("""COMPUTED_VALUE"""),50.720000000000006) -> 50.72 | D4: 329.28 | E4: 46060 | F4: 104 | H4: 150000 | I4: =H4/F4 -> 1442.3077
A5: =IFERROR(__xludf.DUMMYFUNCTION("""COMPUTED_VALUE"""),46066.4891578125) -> 46066.489 | B5: =IFERROR(__xludf.DUMMYFUNCTION("""COMPUTED_VALUE"""),140.0) -> 140 | C5: =IFERROR(__xludf.DUMMYFUNCTION("""COMPUTED_VALUE"""),20.82) -> 20.82 | D5: 119.18 | E5: 46063 | F5: 6 | H5: 7300 | I5: =H5/F5 -> 1216.6667 | K5: COMISION USD 2900 (REUNION CON GER ESE DIA SE PAGO)
A6: =IFERROR(__xludf.DUMMYFUNCTION("""COMPUTED_VALUE"""),46071.321232905095) -> 46071.321 | B6: =IFERROR(__xludf.DUMMYFUNCTION("""COMPUTED_VALUE"""),710.0) -> 710 | C6: =IFERROR(__xludf.DUMMYFUNCTION("""COMPUTED_VALUE"""),85.07199999999999) -> 85.072 | D6: 624.928 | E6: 46063 | F6: 160 | H6: 228000 | I6: =H6/F6 -> 1425 | K6: COMISION USD 5915 17-6
A7: =IFERROR(__xludf.DUMMYFUNCTION("""COMPUTED_VALUE"""),46071.32832734953) -> 46071.328 | B7: =IFERROR(__xludf.DUMMYFUNCTION("""COMPUTED_VALUE"""),110.0) -> 110 | C7: =IFERROR(__xludf.DUMMYFUNCTION("""COMPUTED_VALUE"""),15.130000000000003) -> 15.13 | D7: 94.87 | E7: 46065 | F7: 1306 | H7: 1875000 | I7: =H7/F7 -> 1435.6815 | K7: COMISION USD 4782 25-7
A8: =IFERROR(__xludf.DUMMYFUNCTION("""COMPUTED_VALUE"""),46071.362096689816) -> 46071.362 | B8: =IFERROR(__xludf.DUMMYFUNCTION("""COMPUTED_VALUE"""),110.0) -> 110 | C8: =IFERROR(__xludf.DUMMYFUNCTION("""COMPUTED_VALUE"""),15.130000000000003) -> 15.13 | D8: 94.87 | E8: 46065 | F8: 150 | H8: 215250 | I8: =H8/F8 -> 1435
A9: =IFERROR(__xludf.DUMMYFUNCTION("""COMPUTED_VALUE"""),46072.99220949074) -> 46072.992 | B9: =IFERROR(__xludf.DUMMYFUNCTION("""COMPUTED_VALUE"""),75.0) -> 75 | C9: =IFERROR(__xludf.DUMMYFUNCTION("""COMPUTED_VALUE"""),8.527000000000001) -> 8.527 | D9: 66.473 | E9: 46065 | F9: 160 | H9: 230000 | I9: =H9/F9 -> 1437.5
A10: =IFERROR(__xludf.DUMMYFUNCTION("""COMPUTED_VALUE"""),46073.0) -> 46073 | B10: =IFERROR(__xludf.DUMMYFUNCTION("""COMPUTED_VALUE"""),154.0) -> 154 | D10: 154 | E10: 46066 | F10: 300 | H10: 430000 | I10: =H10/F10 -> 1433.3333
A11: =IFERROR(__xludf.DUMMYFUNCTION("""COMPUTED_VALUE"""),46076.36990046296) -> 46076.37 | B11: =IFERROR(__xludf.DUMMYFUNCTION("""COMPUTED_VALUE"""),680.0) -> 680 | C11: =IFERROR(__xludf.DUMMYFUNCTION("""COMPUTED_VALUE"""),128.802) -> 128.802 | D11: 551.198 | E11: 46066 | F11: 160 | H11: 230400 | I11: =H11/F11 -> 1440
A12: =IFERROR(__xludf.DUMMYFUNCTION("""COMPUTED_VALUE"""),46077.4104953125) -> 46077.41 | B12: =IFERROR(__xludf.DUMMYFUNCTION("""COMPUTED_VALUE"""),720.0) -> 720 | C12: =IFERROR(__xludf.DUMMYFUNCTION("""COMPUTED_VALUE"""),92.51399999999998) -> 92.514 | D12: 627.486 | E12: 46066 | F12: 200 | H12: 288000 | I12: =H12/F12 -> 1440
A13: =IFERROR(__xludf.DUMMYFUNCTION("""COMPUTED_VALUE"""),46086.478767754634) -> 46086.479 | B13: =IFERROR(__xludf.DUMMYFUNCTION("""COMPUTED_VALUE"""),944.0) -> 944 | C13: =IFERROR(__xludf.DUMMYFUNCTION("""COMPUTED_VALUE"""),121.30000000000001) -> 121.3 | D13: 822.7 | E13: 46071 | F13: 314 | H13: 452000 | I13: =H13/F13 -> 1439.4904
A14: =IFERROR(__xludf.DUMMYFUNCTION("""COMPUTED_VALUE"""),46086.501544467596) -> 46086.502 | B14: =IFERROR(__xludf.DUMMYFUNCTION("""COMPUTED_VALUE"""),12.0) -> 12 | C14: =IFERROR(__xludf.DUMMYFUNCTION("""COMPUTED_VALUE"""),2.74) -> 2.74 | D14: 9.26 | E14: 46072 | F14: 80 | H14: 115000 | I14: =H14/F14 -> 1437.5
A15: =IFERROR(__xludf.DUMMYFUNCTION("""COMPUTED_VALUE"""),46091.547995636574) -> 46091.548 | B15: =IFERROR(__xludf.DUMMYFUNCTION("""COMPUTED_VALUE"""),5940.0) -> 5940 | C15: =IFERROR(__xludf.DUMMYFUNCTION("""COMPUTED_VALUE"""),756.9116540649849) -> 756.91165 | D15: 5183.0883 | E15: 46072 | F15: 65 | H15: 94000 | I15: =H15/F15 -> 1446.1538
A16: =IFERROR(__xludf.DUMMYFUNCTION("""COMPUTED_VALUE"""),46091.55504461806) -> 46091.555 | B16: =IFERROR(__xludf.DUMMYFUNCTION("""COMPUTED_VALUE"""),70.0) -> 70 | C16: =IFERROR(__xludf.DUMMYFUNCTION("""COMPUTED_VALUE"""),9.051123596524944) -> 9.0511236 | D16: 60.948876 | E16: 46076 | F16: 2000
A17: =IFERROR(__xludf.DUMMYFUNCTION("""COMPUTED_VALUE"""),46094.90472501158) -> 46094.905 | B17: =IFERROR(__xludf.DUMMYFUNCTION("""COMPUTED_VALUE"""),73.0) -> 73 | C17: =IFERROR(__xludf.DUMMYFUNCTION("""COMPUTED_VALUE"""),8.722999999999999) -> 8.723 | D17: 64.277 | E17: 46077 | F17: 678 | H17: 969540 | I17: =H17/F17 -> 1430
A18: =IFERROR(__xludf.DUMMYFUNCTION("""COMPUTED_VALUE"""),46100.40611190972) -> 46100.406 | B18: =IFERROR(__xludf.DUMMYFUNCTION("""COMPUTED_VALUE"""),2850.0) -> 2850 | C18: =IFERROR(__xludf.DUMMYFUNCTION("""COMPUTED_VALUE"""),326.85029) -> 326.85029 | D18: 2523.1497 | E18: 46078 | F18: 150 | H18: 215250 | I18: =H18/F18 -> 1435
A19: =IFERROR(__xludf.DUMMYFUNCTION("""COMPUTED_VALUE"""),46100.42895394676) -> 46100.429 | B19: =IFERROR(__xludf.DUMMYFUNCTION("""COMPUTED_VALUE"""),111.0) -> 111 | C19: =IFERROR(__xludf.DUMMYFUNCTION("""COMPUTED_VALUE"""),13.518) -> 13.518 | D19: 97.482 | E19: 46079 | F19: 500 | H19: 722500 | I19: =H19/F19 -> 1445
